Workbook

Sheet Base
A1: Income | B1: Kidhome | C1: Teenhome | D1: Recency | E1: MntWines | F1: MntFruits | G1: MntMeatProducts | H1: MntFishProducts | I1: MntSweetProducts | J1: MntGoldProds | K1: NumDealsPurchases | L1: NumWebPurchases | M1: NumCatalogPurchases | N1: NumStorePurchases | O1: NumWebVisitsMonth | P1: AcceptedCmp3 | Q1: AcceptedCmp4 | R1: AcceptedCmp5 | S1: AcceptedCmp1 | T1: AcceptedCmp2 | U1: Complain | V1: Z_CostContact | W1: Z_Revenue | X1: Response | Y1: Age | Z1: Customer_Days | AA1: marital_Divorced | AB1: marital_Married | AC1: marital_Single | AD1: marital_Together | AE1: marital_Widow | AF1: education_2n Cycle | AG1: education_Basic | AH1: education_Graduation | AI1: education_Master | AJ1: education_PhD | AK1: MntTotal | AL1: MntRegularProds | AM1: AcceptedCmpOverall
A2: 58138.0 | B2: 0 | C2: 0 | D2: 58 | E2: 635 | F2: 88 | G2: 546 | H2: 172 | I2: 88 | J2: 88 | K2: 3 | L2: 8 | M2: 10 | N2: 4 | O2: 7 | P2: 0 | Q2: 0 | R2: 0 | S2: 0 | T2: 0 | U2: 0 | V2: 3 | W2: 11 | X2: 1 | Y2: 63 | Z2: 2822 | AA2: 0 | AB2: 0 | AC2: 1 | AD2: 0 | AE2: 0 | AF2: 0 | AG2: 0 | AH2: 1 | AI2: 0 | AJ2: 0 | AK2: 1529 | AL2: 1441 | AM2: 0
A3: 46344.0 | B3: 1 | C3: 1 | D3: 38 | E3: 11 | F3: 1 | G3: 6 | H3: 2 | I3: 1 | J3: 6 | K3: 2 | L3: 1 | M3: 1 | N3: 2 | O3: 5 | P3: 0 | Q3: 0 | R3: 0 | S3: 0 | T3: 0 | U3: 0 | V3: 3 | W3: 11 | X3: 0 | Y3: 66 | Z3: 2272 | AA3: 0 | AB3: 0 | AC3: 1 | AD3: 0 | AE3: 0 | AF3: 0 | AG3: 0 | AH3: 1 | AI3: 0 | AJ3: 0 | AK3: 21 | AL3: 15 | AM3: 0
A4: 71613.0 | B4: 0 | C4: 0 | D4: 26 | E4: 426 | F4: 49 | G4: 127 | H4: 111 | I4: 21 | J4: 42 | K4: 1 | L4: 8 | M4: 2 | N4: 10 | O4: 4 | P4: 0 | Q4: 0 | R4: 0 | S4: 0 | T4: 0 | U4: 0 | V4: 3 | W4: 11 | X4: 0 | Y4: 55 | Z4: 2471 | AA4: 0 | AB4: 0 | AC4: 0 | AD4: 1 | AE4: 0 | AF4: 0 | AG4: 0 | AH4: 1 | AI4: 0 | AJ4: 0 | AK4: 734 | AL4: 692 | AM4: 0
A5: 26646.0 | B5: 1 | C5: 0 | D5: 26 | E5: 11 | F5: 4 | G5: 20 | H5: 10 | I5: 3 | J5: 5 | K5: 2 | L5: 2 | M5: 0 | N5: 4 | O5: 6 | P5: 0 | Q5: 0 | R5: 0 | S5: 0 | T5: 0 | U5: 0 | V5: 3 | W5: 11 | X5: 0 | Y5: 36 | Z5: 2298 | AA5: 0 | AB5: 0 | AC5: 0 | AD5: 1 | AE5: 0 | AF5: 0 | AG5: 0 | AH5: 1 | AI5: 0 | AJ5: 0 | AK5: 48 | AL5: 43 | AM5: 0
A6: 58293.0 | B6: 1 | C6: 0 | D6: 94 | E6: 173 | F6: 43 | G6: 118 | H6: 46 | I6: 27 | J6: 15 | K6: 5 | L6: 5 | M6: 3 | N6: 6 | O6: 5 | P6: 0 | Q6: 0 | R6: 0 | S6: 0 | T6: 0 | U6: 0 | V6: 3 | W6: 11 | X6: 0 | Y6: 39 | Z6: 2320 | AA6: 0 | AB6: 1 | AC6: 0 | AD6: 0 | AE6: 0 | AF6: 0 | AG6: 0 | AH6: 0 | AI6: 0 | AJ6: 1 | AK6: 407 | AL6: 392 | AM6: 0
A7: 62513.0 | B7: 0 | C7: 1 | D7: 16 | E7: 520 | F7: 42 | G7: 98 | H7: 0 | I7: 42 | J7: 14 | K7: 2 | L7: 6 | M7: 4 | N7: 10 | O7: 6 | P7: 0 | Q7: 0 | R7: 0 | S7: 0 | T7: 0 | U7: 0 | V7: 3 | W7: 11 | X7: 0 | Y7: 53 | Z7: 2452 | AA7: 0 | AB7: 0 | AC7: 0 | AD7: 1 | AE7: 0 | AF7: 0 | AG7: 0 | AH7: 0 | AI7: 1 | AJ7: 0 | AK7: 702 | AL7: 688 | AM7: 0
A8: 55635.0 | B8: 0 | C8: 1 | D8: 34 | E8: 235 | F8: 65 | G8: 164 | H8: 50 | I8: 49 | J8: 27 | K8: 4 | L8: 7 | M8: 3 | N8: 7 | O8: 6 | P8: 0 | Q8: 0 | R8: 0 | S8: 0 | T8: 0 | U8: 0 | V8: 3 | W8: 11 | X8: 0 | Y8: 49 | Z8: 2752 | AA8: 1 | AB8: 0 | AC8: 0 | AD8: 0 | AE8: 0 | AF8: 0 | AG8: 0 | AH8: 1 | AI8: 0 | AJ8: 0 | AK8: 563 | AL8: 536 | AM8: 0
A9: 33454.0 | B9: 1 | C9: 0 | D9: 32 | E9: 76 | F9: 10 | G9: 56 | H9: 3 | I9: 1 | J9: 23 | K9: 2 | L9: 4 | M9: 0 | N9: 4 | O9: 8 | P9: 0 | Q9: 0 | R9: 0 | S9: 0 | T9: 0 | U9: 0 | V9: 3 | W9: 11 | X9: 0 | Y9: 35 | Z9: 2576 | AA9: 0 | AB9: 1 | AC9: 0 | AD9: 0 | AE9: 0 | AF9: 0 | AG9: 0 | AH9: 0 | AI9: 0 | AJ9: 1 | AK9: 146 | AL9: 123 | AM9: 0
A10: 30351.0 | B10: 1 | C10: 0 | D10: 19 | E10: 14 | F10: 0 | G10: 24 | H10: 3 | I10: 3 | J10: 2 | K10: 1 | L10: 3 | M10: 0 | N10: 2 | O10: 9 | P10: 0 | Q10: 0 | R10: 0 | S10: 0 | T10: 0 | U10: 0 | V10: 3 | W10: 11 | X10: 1 | Y10: 46 | Z10: 2547 | AA10: 0 | AB10: 0 | AC10: 0 | AD10: 1 | AE10: 0 | AF10: 0 | AG10: 0 | AH10: 0 | AI10: 0 | AJ10: 1 | AK10: 44 | AL10: 42 | AM10: 0
A11: 5648.0 | B11: 1 | C11: 1 | D11: 68 | E11: 28 | F11: 0 | G11: 6 | H11: 1 | I11: 1 | J11: 13 | K11: 1 | L11: 1 | M11: 0 | N11: 0 | O11: 20 | P11: 1 | Q11: 0 | R11: 0 | S11: 0 | T11: 0 | U11: 0 | V11: 3 | W11: 11 | X11: 0 | Y11: 70 | Z11: 2267 | AA11: 0 | AB11: 0 | AC11: 0 | AD11: 1 | AE11: 0 | AF11: 0 | AG11: 0 | AH11: 0 | AI11: 0 | AJ11: 1 | AK11: 36 | AL11: 23 | AM11: 1
A12: 7500.0 | B12: 0 | C12: 0 | D12: 59 | E12: 6 | F12: 16 | G12: 11 | H12: 11 | I12: 1 | J12: 16 | K12: 1 | L12: 2 | M12: 0 | N12: 3 | O12: 8 | P12: 0 | Q12: 0 | R12: 0 | S12: 0 | T12: 0 | U12: 0 | V12: 3 | W12: 11 | X12: 0 | Y12: 44 | Z12: 2752 | AA12: 0 | AB12: 1 | AC12: 0 | AD12: 0 | AE12: 0 | AF12: 0 | AG12: 1 | AH12: 0 | AI12: 0 | AJ12: 0 | AK12: 45 | AL12: 29 | AM12: 0
A13: 63033.0 | B13: 0 | C13: 0 | D13: 82 | E13: 194 | F13: 61 | G13: 480 | H13: 225 | I13: 112 | J13: 30 | K13: 1 | L13: 3 | M13: 4 | N13: 8 | O13: 2 | P13: 0 | Q13: 0 | R13: 0 | S13: 0 | T13: 0 | U13: 0 | V13: 3 | W13: 11 | X13: 0 | Y13: 61 | Z13: 2385 | AA13: 1 | AB13: 0 | AC13: 0 | AD13: 0 | AE13: 0 | AF13: 0 | AG13: 0 | AH13: 1 | AI13: 0 | AJ13: 0 | AK13: 1072 | AL13: 1042 | AM13: 0
... A2206: 52869.0 | B2206: 1 | C2206: 1 | D2206: 40 | E2206: 84 | F2206: 3 | G2206: 61 | H2206: 2 | I2206: 1 | J2206: 21 | K2206: 3 | L2206: 3 | M2206: 1 | N2206: 4 | O2206: 7 | P2206: 0 | Q2206: 0 | R2206: 0 | S2206: 0 | T2206: 0 | U2206: 0 | V2206: 3 | W2206: 11 | X2206: 1 | Y2206: 66 | Z2206: 2781 | AA2206: 0 | AB2206: 1 | AC2206: 0 | AD2206: 0 | AE2206: 0 | AF2206: 0 | AG2206: 0 | AH2206: 0 | AI2206: 0 | AJ2206: 1 | AK2206: 151 | AL2206: 130 | AM2206: 0

Sheet Base tratada
A1: ID | B1: Income | C1: Kidhome | D1: Teenhome | E1: Recency | F1: Faixa Recência | G1: Age | H1: Faixa Idade | I1: Customer_Days | J1: Estado Civil | K1: marital_Divorced | L1: marital_Married | M1: marital_Single | N1: marital_Together | O1: marital_Widow | P1: education_2n Cycle | Q1: education_Basic | R1: education_Graduation | S1: education_Master | T1: education_PhD | U1: MntWines | V1: MntFruits | W1: MntMeatProducts | X1: MntFishProducts | Y1: MntSweetProducts | Z1: MntGoldProds | AA1: NumDealsPurchases | AB1: NumWebVisitsMonth | AC1: NumWebPurchases | AD1: NumCatalogPurchases | AE1: NumStorePurchases | AF1: Total de Compras | AG1: Faixa Total de Compras | AH1: Canal Predominante | AI1: Ticket médio | AJ1: Faixa ticket médio | AK1: MntTotal | AL1: Faixa Gasto | AM1: AcceptedCmp1 | AN1: AcceptedCmp2 | AO1: AcceptedCmp3 | AP1: AcceptedCmp4 | AQ1: AcceptedCmp5 | AR1: AcceptedCmpOverall | AS1: Complain | AT1: Z_CostContact | AU1: Z_Revenue | AV1: MntRegularProds | AW1: Response | AX1: Categorização Response | AY1: Segmento | AZ1: Segmento Lucrativo
A2: 1 | B2: 58138 | C2: 0 | D2: 0 | E2: 58 | F2: =IF('Base tratada'!$E2<=15,"0-15 dias", IF('Base tratada'!$E2<=30, "16-30 dias", IF('Base tratada'!$E2<=45, "31-45 dias", IF('Base tratada'!$E2<=60, "46-60 dias", IF('Base tratada'!$E2<=75, "61-75 dias", "76-99 dias"))))) -> 46-60 dias | G2: 63 | H2: =IF('Base tratada'!$G2<=29,"24–29", IF('Base tratada'!$G2<=39,"30–39", IF('Base tratada'!$G2<=49,"40–49", IF('Base tratada'!$G2<=59,"50–59", IF('Base tratada'!$G2<=69,"60–69", "70–80"))))) -> 60–69 | I2: 2822 | J2: =IF('Base tratada'!$K2=1,"Divorciado", IF('Base tratada'!$L2=1,"Casado", IF('Base tratada'!$M2=1, "Solteiro", IF('Base tratada'!$N2=1,"Juntos", "Viúvo")))) -> Solteiro | K2: 0 | L2: 0 | M2: 1 | N2: 0 | O2: 0 | P2: 0 | Q2: 0 | R2: 1 | S2: 0 | T2: 0 | U2: 635 | V2: 88 | W2: 546 | X2: 172 | Y2: 88 | Z2: 88 | AA2: 3 | AB2: 7 | AC2: 8 | AD2: 10 | AE2: 4 | AF2: ='Base tratada'!$AC2+'Base tratada'!$AD2+'Base tratada'!$AE2 -> 22 | AG2: =IF(Tabela3[[#This Row],[Total de Compras]]=0,"0", IF(Tabela3[[#This Row],[Total de Compras]]<=4,"1–4", IF(Tabela3[[#This Row],[Total de Compras]]<=10,"5–10", IF(Tabela3[[#This Row],[Total de Compras]]<=15,"11–15", IF(Tabela3[[#This Row],[Total de Compras]]<=20,"16–20", "+20"))))) -> +20 | AH2: =IF('Base tratada'!$AC2>=MAX('Base tratada'!$AD2,'Base tratada'!$AE2),"Web", IF('Base tratada'!$AD2>='Base tratada'!$AE2,"Catalog", "Store")) -> Catalog | AI2: =IF('Base tratada'!$AF2=0,"0",'Base tratada'!$AK2/'Base tratada'!$AF2) -> 69.5 | AJ2: =IF('Base tratada'!$AI2=0,"R$ 0", IF('Base tratada'!$AI2<=25,"R$ 1–25", IF('Base tratada'!$AI2<=50,"R$ 26–50", "+R$ 50"))) -> +R$ 50 | AK2: 1529 | AL2: =IF('Base tratada'!$AK2<=100,"R$ 0-100", IF('Base tratada'!$AK2<=500,"R$ 101-500", IF('Base tratada'!$AK2<=1000,"R$ 501-1000", IF('Base tratada'!$AK2<=1500,"R$ 1001-1500", "+R$ 1500")))) -> +R$ 1500 | AM2: 0 | AN2: 0 | AO2: 0 | AP2: 0 | AQ2: 0 | AR2: 0 | AS2: 0 | AT2: 3 | AU2: 11 | AV2: 1441 | AW2: 1 | AX2: =IF(Tabela3[[#This Row],[Response]]=1, "Aceitou", "Não aceitou") -> Aceitou | AY2: =Tabela3[[#This Row],[Faixa Recência]] & " | " & Tabela3[[#This Row],[Faixa Gasto]] & " | " & Tabela3[[#This Row],[Faixa ticket médio]] -> 46-60 dias | +R$ 1500 | +R$ 50 | AZ2: =IF(OR( AND(Tabela3[[#This Row],[Recency]]<=30,Tabela3[[#This Row],[MntTotal]]>=1000,Tabela3[[#This Row],[MntTotal]]>=50), AND(AND(Tabela3[[#This Row],[Recency]]>30,Tabela3[[#This Row],[Recency]]<=45), OR(Tabela3[[#This Row],[MntTotal]]>=1500,Tabela3[[#This Row],[Ticket médio]]>=50)) ),"SIM","NÃO") -> NÃO
A3: 2 | B3: 46344 | C3: 1 | D3: 1 | E3: 38 | F3: =IF('Base tratada'!$E3<=15,"0-15 dias", IF('Base tratada'!$E3<=30, "16-30 dias", IF('Base tratada'!$E3<=45, "31-45 dias", IF('Base tratada'!$E3<=60, "46-60 dias", IF('Base tratada'!$E3<=75, "61-75 dias", "76-99 dias"))))) -> 31-45 dias | G3: 66 | H3: =IF('Base tratada'!$G3<=29,"24–29", IF('Base tratada'!$G3<=39,"30–39", IF('Base tratada'!$G3<=49,"40–49", IF('Base tratada'!$G3<=59,"50–59", IF('Base tratada'!$G3<=69,"60–69", "70–80"))))) -> 60–69 | I3: 2272 | J3: =IF('Base tratada'!$K3=1,"Divorciado", IF('Base tratada'!$L3=1,"Casado", IF('Base tratada'!$M3=1, "Solteiro", IF('Base tratada'!$N3=1,"Juntos", "Viúvo")))) -> Solteiro | K3: 0 | L3: 0 | M3: 1 | N3: 0 | O3: 0 | P3: 0 | Q3: 0 | R3: 1 | S3: 0 | T3: 0 | U3: 11 | V3: 1 | W3: 6 | X3: 2 | Y3: 1 | Z3: 6 | AA3: 2 | AB3: 5 | AC3: 1 | AD3: 1 | AE3: 2 | AF3: ='Base tratada'!$AC3+'Base tratada'!$AD3+'Base tratada'!$AE3 -> 4 | AG3: =IF(Tabela3[[#This Row],[Total de Compras]]=0,"0", IF(Tabela3[[#This Row],[Total de Compras]]<=4,"1–4", IF(Tabela3[[#This Row],[Total de Compras]]<=10,"5–10", IF(Tabela3[[#This Row],[Total de Compras]]<=15,"11–15", IF(Tabela3[[#This Row],[Total de Compras]]<=20,"16–20", "+20"))))) -> 1–4 | AH3: =IF('Base tratada'!$AC3>=MAX('Base tratada'!$AD3,'Base tratada'!$AE3),"Web", IF('Base tratada'!$AD3>='Base tratada'!$AE3,"Catalog", "Store")) -> Store | AI3: =IF('Base tratada'!$AF3=0,"0",'Base tratada'!$AK3/'Base tratada'!$AF3) -> 5.25 | AJ3: =IF('Base tratada'!$AI3=0,"R$ 0", IF('Base tratada'!$AI3<=25,"R$ 1–25", IF('Base tratada'!$AI3<=50,"R$ 26–50", "+R$ 50"))) -> R$ 1–25 | AK3: 21 | AL3: =IF('Base tratada'!$AK3<=100,"R$ 0-100", IF('Base tratada'!$AK3<=500,"R$ 101-500", IF('Base tratada'!$AK3<=1000,"R$ 501-1000", IF('Base tratada'!$AK3<=1500,"R$ 1001-1500", "+R$ 1500")))) -> R$ 0-100 | AM3: 0 | AN3: 0 | AO3: 0 | AP3: 0 | AQ3: 0 | AR3: 0 | AS3: 0 | AT3: 3 | AU3: 11 | AV3: 15 | AW3: 0 | AX3: =IF(Tabela3[[#This Row],[Response]]=1, "Aceitou", "Não aceitou") -> Não aceitou | AY3: =Tabela3[[#This Row],[Faixa Recência]] & " | " & Tabela3[[#This Row],[Faixa Gasto]] & " | " & Tabela3[[#This Row],[Faixa ticket médio]] -> 31-45 dias | R$ 0-100 | R$ 1–25 | AZ3: =IF(OR( AND(Tabela3[[#This Row],[Recency]]<=30,Tabela3[[#This Row],[MntTotal]]>=1000,Tabela3[[#This Row],[MntTotal]]>=50), AND(AND(Tabela3[[#This Row],[Recency]]>30,Tabela3[[#This Row],[Recency]]<=45), OR(Tabela3[[#This Row],[MntTotal]]>=1500,Tabela3[[#This Row],[Ticket médio]]>=50)) ),"SIM","NÃO") -> NÃO
A4: 3 | B4: 71613 | C4: 0 | D4: 0 | E4: 26 | F4: =IF('Base tratada'!$E4<=15,"0-15 dias", IF('Base tratada'!$E4<=30, "16-30 dias", IF('Base tratada'!$E4<=45, "31-45 dias", IF('Base tratada'!$E4<=60, "46-60 dias", IF('Base tratada'!$E4<=75, "61-75 dias", "76-99 dias"))))) -> 16-30 dias | G4: 55 | H4: =IF('Base tratada'!$G4<=29,"24–29", IF('Base tratada'!$G4<=39,"30–39", IF('Base tratada'!$G4<=49,"40–49", IF('Base tratada'!$G4<=59,"50–59", IF('Base tratada'!$G4<=69,"60–69", "70–80"))))) -> 50–59 | I4: 2471 | J4: =IF('Base tratada'!$K4=1,"Divorciado", IF('Base tratada'!$L4=1,"Casado", IF('Base tratada'!$M4=1, "Solteiro", IF('Base tratada'!$N4=1,"Juntos", "Viúvo")))) -> Juntos | K4: 0 | L4: 0 | M4: 0 | N4: 1 | O4: 0 | P4: 0 | Q4: 0 | R4: 1 | S4: 0 | T4: 0 | U4: 426 | V4: 49 | W4: 127 | X4: 111 | Y4: 21 | Z4: 42 | AA4: 1 | AB4: 4 | AC4: 8 | AD4: 2 | AE4: 10 | AF4: ='Base tratada'!$AC4+'Base tratada'!$AD4+'Base tratada'!$AE4 -> 20 | AG4: =IF(Tabela3[[#This Row],[Total de Compras]]=0,"0", IF(Tabela3[[#This Row],[Total de Compras]]<=4,"1–4", IF(Tabela3[[#This Row],[Total de Compras]]<=10,"5–10", IF(Tabela3[[#This Row],[Total de Compras]]<=15,"11–15", IF(Tabela3[[#This Row],[Total de Compras]]<=20,"16–20", "+20"))))) -> 16–20 | AH4: =IF('Base tratada'!$AC4>=MAX('Base tratada'!$AD4,'Base tratada'!$AE4),"Web", IF('Base tratada'!$AD4>='Base tratada'!$AE4,"Catalog", "Store")) -> Store | AI4: =IF('Base tratada'!$AF4=0,"0",'Base tratada'!$AK4/'Base tratada'!$AF4) -> 36.7 | AJ4: =IF('Base tratada'!$AI4=0,"R$ 0", IF('Base tratada'!$AI4<=25,"R$ 1–25", IF('Base tratada'!$AI4<=50,"R$ 26–50", "+R$ 50"))) -> R$ 26–50 | AK4: 734 | AL4: =IF('Base tratada'!$AK4<=100,"R$ 0-100", IF('Base tratada'!$AK4<=500,"R$ 101-500", IF('Base tratada'!$AK4<=1000,"R$ 501-1000", IF('Base tratada'!$AK4<=1500,"R$ 1001-1500", "+R$ 1500")))) -> R$ 501-1000 | AM4: 0 | AN4: 0 | AO4: 0 | AP4: 0 | AQ4: 0 | AR4: 0 | AS4: 0 | AT4: 3 | AU4: 11 | AV4: 692 | AW4: 0 | AX4: =IF(Tabela3[[#This Row],[Response]]=1, "Aceitou", "Não aceitou") -> Não aceitou | AY4: =Tabela3[[#This Row],[Faixa Recência]] & " | " & Tabela3[[#This Row],[Faixa Gasto]] & " | " & Tabela3[[#This Row],[Faixa ticket médio]] -> 16-30 dias | R$ 501-1000 | R$ 26–50 | AZ4: =IF(OR( AND(Tabela3[[#This Row],[Recency]]<=30,Tabela3[[#This Row],[MntTotal]]>=1000,Tabela3[[#This Row],[MntTotal]]>=50), AND(AND(Tabela3[[#This Row],[Recency]]>30,Tabela3[[#This Row],[Recency]]<=45), OR(Tabela3[[#This Row],[MntTotal]]>=1500,Tabela3[[#This Row],[Ticket médio]]>=50)) ),"SIM","NÃO") -> NÃO
A5: 4 | B5: 26646 | C5: 1 | D5: 0 | E5: 26 | F5: =IF('Base tratada'!$E5<=15,"0-15 dias", IF('Base tratada'!$E5<=30, "16-30 dias", IF('Base tratada'!$E5<=45, "31-45 dias", IF('Base tratada'!$E5<=60, "46-60 dias", IF('Base tratada'!$E5<=75, "61-75 dias", "76-99 dias"))))) -> 16-30 dias | G5: 36 | H5: =IF('Base tratada'!$G5<=29,"24–29", IF('Base tratada'!$G5<=39,"30–39", IF('Base tratada'!$G5<=49,"40–49", IF('Base tratada'!$G5<=59,"50–59", IF('Base tratada'!$G5<=69,"60–69", "70–80"))))) -> 30–39 | I5: 2298 | J5: =IF('Base tratada'!$K5=1,"Divorciado", IF('Base tratada'!$L5=1,"Casado", IF('Base tratada'!$M5=1, "Solteiro", IF('Base tratada'!$N5=1,"Juntos", "Viúvo")))) -> Juntos | K5: 0 | L5: 0 | M5: 0 | N5: 1 | O5: 0 | P5: 0 | Q5: 0 | R5: 1 | S5: 0 | T5: 0 | U5: 11 | V5: 4 | W5: 20 | X5: 10 | Y5: 3 | Z5: 5 | AA5: 2 | AB5: 6 | AC5: 2 | AD5: 0 | AE5: 4 | AF5: ='Base tratada'!$AC5+'Base tratada'!$AD5+'Base tratada'!$AE5 -> 6 | AG5: =IF(Tabela3[[#This Row],[Total de Compras]]=0,"0", IF(Tabela3[[#This Row],[Total de Compras]]<=4,"1–4", IF(Tabela3[[#This Row],[Total de Compras]]<=10,"5–10", IF(Tabela3[[#This Row],[Total de Compras]]<=15,"11–15", IF(Tabela3[[#This Row],[Total de Compras]]<=20,"16–20", "+20"))))) -> 5–10 | AH5: =IF('Base tratada'!$AC5>=MAX('Base tratada'!$AD5,'Base tratada'!$AE5),"Web", IF('Base tratada'!$AD5>='Base tratada'!$AE5,"Catalog", "Store")) -> Store | AI5: =IF('Base tratada'!$AF5=0,"0",'Base tratada'!$AK5/'Base tratada'!$AF5) -> 8 | AJ5: =IF('Base tratada'!$AI5=0,"R$ 0", IF('Base tratada'!$AI5<=25,"R$ 1–25", IF('Base tratada'!$AI5<=50,"R$ 26–50", "+R$ 50"))) -> R$ 1–25 | AK5: 48 | AL5: =IF('Base tratada'!$AK5<=100,"R$ 0-100", IF('Base tratada'!$AK5<=500,"R$ 101-500", IF('Base tratada'!$AK5<=1000,"R$ 501-1000", IF('Base tratada'!$AK5<=1500,"R$ 1001-1500", "+R$ 1500")))) -> R$ 0-100 | AM5: 0 | AN5: 0 | AO5: 0 | AP5: 0 | AQ5: 0 | AR5: 0 | AS5: 0 | AT5: 3 | AU5: 11 | AV5: 43 | AW5: 0 | AX5: =IF(Tabela3[[#This Row],[Response]]=1, "Aceitou", "Não aceitou") -> Não aceitou | AY5: =Tabela3[[#This Row],[Faixa Recência]] & " | " & Tabela3[[#This Row],[Faixa Gasto]] & " | " & Tabela3[[#This Row],[Faixa ticket médio]] -> 16-30 dias | R$ 0-100 | R$ 1–25 | AZ5: =IF(OR( AND(Tabela3[[#This Row],[Recency]]<=30,Tabela3[[#This Row],[MntTotal]]>=1000,Tabela3[[#This Row],[MntTotal]]>=50), AND(AND(Tabela3[[#This Row],[Recency]]>30,Tabela3[[#This Row],[Recency]]<=45), OR(Tabela3[[#This Row],[MntTotal]]>=1500,Tabela3[[#This Row],[Ticket médio]]>=50)) ),"SIM","NÃO") -> NÃO
A6: 5 | B6: 58293 | C6: 1 | D6: 0 | E6: 94 | F6: =IF('Base tratada'!$E6<=15,"0-15 dias", IF('Base tratada'!$E6<=30, "16-30 dias", IF('Base tratada'!$E6<=45, "31-45 dias", IF('Base tratada'!$E6<=60, "46-60 dias", IF('Base tratada'!$E6<=75, "61-75 dias", "76-99 dias"))))) -> 76-99 dias | G6: 39 | H6: =IF('Base tratada'!$G6<=29,"24–29", IF('Base tratada'!$G6<=39,"30–39", IF('Base tratada'!$G6<=49,"40–49", IF('Base tratada'!$G6<=59,"50–59", IF('Base tratada'!$G6<=69,"60–69", "70–80"))))) -> 30–39 | I6: 2320 | J6: =IF('Base tratada'!$K6=1,"Divorciado", IF('Base tratada'!$L6=1,"Casado", IF('Base tratada'!$M6=1, "Solteiro", IF('Base tratada'!$N6=1,"Juntos", "Viúvo")))) -> Casado | K6: 0 | L6: 1 | M6: 0 | N6: 0 | O6: 0 | P6: 0 | Q6: 0 | R6: 0 | S6: 0 | T6: 1 | U6: 173 | V6: 43 | W6: 118 | X6: 46 | Y6: 27 | Z6: 15 | AA6: 5 | AB6: 5 | AC6: 5 | AD6: 3 | AE6: 6 | AF6: ='Base tratada'!$AC6+'Base tratada'!$AD6+'Base tratada'!$AE6 -> 14 | AG6: =IF(Tabela3[[#This Row],[Total de Compras]]=0,"0", IF(Tabela3[[#This Row],[Total de Compras]]<=4,"1–4", IF(Tabela3[[#This Row],[Total de Compras]]<=10,"5–10", IF(Tabela3[[#This Row],[Total de Compras]]<=15,"11–15", IF(Tabela3[[#This Row],[Total de Compras]]<=20,"16–20", "+20"))))) -> 11–15 | AH6: =IF('Base tratada'!$AC6>=MAX('Base tratada'!$AD6,'Base tratada'!$AE6),"Web", IF('Base tratada'!$AD6>='Base tratada'!$AE6,"Catalog", "Store")) -> Store | AI6: =IF('Base tratada'!$AF6=0,"0",'Base tratada'!$AK6/'Base tratada'!$AF6) -> 29.071429 | AJ6: =IF('Base tratada'!$AI6=0,"R$ 0", IF('Base tratada'!$AI6<=25,"R$ 1–25", IF('Base tratada'!$AI6<=50,"R$ 26–50", "+R$ 50"))) -> R$ 26–50 | AK6: 407 | AL6: =IF('Base tratada'!$AK6<=100,"R$ 0-100", IF('Base tratada'!$AK6<=500,"R$ 101-500", IF('Base tratada'!$AK6<=1000,"R$ 501-1000", IF('Base tratada'!$AK6<=1500,"R$ 1001-1500", "+R$ 1500")))) -> R$ 101-500 | AM6: 0 | AN6: 0 | AO6: 0 | AP6: 0 | AQ6: 0 | AR6: 0 | AS6: 0 | AT6: 3 | AU6: 11 | AV6: 392 | AW6: 0 | AX6: =IF(Tabela3[[#This Row],[Response]]=1, "Aceitou", "Não aceitou") -> Não aceitou | AY6: =Tabela3[[#This Row],[Faixa Recência]] & " | " & Tabela3[[#This Row],[Faixa Gasto]] & " | " & Tabela3[[#This Row],[Faixa ticket médio]] -> 76-99 dias | R$ 101-500 | R$ 26–50 | AZ6: =IF(OR( AND(Tabela3[[#This Row],[Recency]]<=30,Tabela3[[#This Row],[MntTotal]]>=1000,Tabela3[[#This Row],[MntTotal]]>=50), AND(AND(Tabela3[[#This Row],[Recency]]>30,Tabela3[[#This Row],[Recency]]<=45), OR(Tabela3[[#This Row],[MntTotal]]>=1500,Tabela3[[#This Row],[Ticket médio]]>=50)) ),"SIM","NÃO") -> NÃO
A7: 6 | B7: 62513 | C7: 0 | D7: 1 | E7: 16 | F7: =IF('Base tratada'!$E7<=15,"0-15 dias", IF('Base tratada'!$E7<=30, "16-30 dias", IF('Base tratada'!$E7<=45, "31-45 dias", IF('Base tratada'!$E7<=60, "46-60 dias", IF('Base tratada'!$E7<=75, "61-75 dias", "76-99 dias"))))) -> 16-30 dias | G7: 53 | H7: =IF('Base tratada'!$G7<=29,"24–29", IF('Base tratada'!$G7<=39,"30–39", IF('Base tratada'!$G7<=49,"40–49", IF('Base tratada'!$G7<=59,"50–59", IF('Base tratada'!$G7<=69,"60–69", "70–80"))))) -> 50–59 | I7: 2452 | J7: =IF('Base tratada'!$K7=1,"Divorciado", IF('Base tratada'!$L7=1,"Casado", IF('Base tratada'!$M7=1, "Solteiro", IF('Base tratada'!$N7=1,"Juntos", "Viúvo")))) -> Juntos | K7: 0 | L7: 0 | M7: 0 | N7: 1 | O7: 0 | P7: 0 | Q7: 0 | R7: 0 | S7: 1 | T7: 0 | U7: 520 | V7: 42 | W7: 98 | X7: 0 | Y7: 42 | Z7: 14 | AA7: 2 | AB7: 6 | AC7: 6 | AD7: 4 | AE7: 10 | AF7: ='Base tratada'!$AC7+'Base tratada'!$AD7+'Base tratada'!$AE7 -> 20 | AG7: =IF(Tabela3[[#This Row],[Total de Compras]]=0,"0", IF(Tabela3[[#This Row],[Total de Compras]]<=4,"1–4", IF(Tabela3[[#This Row],[Total de Compras]]<=10,"5–10", IF(Tabela3[[#This Row],[Total de Compras]]<=15,"11–15", IF(Tabela3[[#This Row],[Total de Compras]]<=20,"16–20", "+20"))))) -> 16–20 | AH7: =IF('Base tratada'!$AC7>=MAX('Base tratada'!$AD7,'Base tratada'!$AE7),"Web", IF('Base tratada'!$AD7>='Base tratada'!$AE7,"Catalog", "Store")) -> Store | AI7: =IF('Base tratada'!$AF7=0,"0",'Base tratada'!$AK7/'Base tratada'!$AF7) -> 35.1 | AJ7: =IF('Base tratada'!$AI7=0,"R$ 0", IF('Base tratada'!$AI7<=25,"R$ 1–25", IF('Base tratada'!$AI7<=50,"R$ 26–50", "+R$ 50"))) -> R$ 26–50 | AK7: 702 | AL7: =IF('Base tratada'!$AK7<=100,"R$ 0-100", IF('Base tratada'!$AK7<=500,"R$ 101-500", IF('Base tratada'!$AK7<=1000,"R$ 501-1000", IF('Base tratada'!$AK7<=1500,"R$ 1001-1500", "+R$ 1500")))) -> R$ 501-1000 | AM7: 0 | AN7: 0 | AO7: 0 | AP7: 0 | AQ7: 0 | AR7: 0 | AS7: 0 | AT7: 3 | AU7: 11 | AV7: 688 | AW7: 0 | AX7: =IF(Tabela3[[#This Row],[Response]]=1, "Aceitou", "Não aceitou") -> Não aceitou | AY7: =Tabela3[[#This Row],[Faixa Recência]] & " | " & Tabela3[[#This Row],[Faixa Gasto]] & " | " & Tabela3[[#This Row],[Faixa ticket médio]] -> 16-30 dias | R$ 501-1000 | R$ 26–50 | AZ7: =IF(OR( AND(Tabela3[[#This Row],[Recency]]<=30,Tabela3[[#This Row],[MntTotal]]>=1000,Tabela3[[#This Row],[MntTotal]]>=50), AND(AND(Tabela3[[#This Row],[Recency]]>30,Tabela3[[#This Row],[Recency]]<=45), OR(Tabela3[[#This Row],[MntTotal]]>=1500,Tabela3[[#This Row],[Ticket médio]]>=50)) ),"SIM","NÃO") -> NÃO
A8: 7 | B8: 55635 | C8: 0 | D8: 1 | E8: 34 | F8: =IF('Base tratada'!$E8<=15,"0-15 dias", IF('Base tratada'!$E8<=30, "16-30 dias", IF('Base tratada'!$E8<=45, "31-45 dias", IF('Base tratada'!$E8<=60, "46-60 dias", IF('Base tratada'!$E8<=75, "61-75 dias", "76-99 dias"))))) -> 31-45 dias | G8: 49 | H8: =IF('Base tratada'!$G8<=29,"24–29", IF('Base tratada'!$G8<=39,"30–39", IF('Base tratada'!$G8<=49,"40–49", IF('Base tratada'!$G8<=59,"50–59", IF('Base tratada'!$G8<=69,"60–69", "70–80"))))) -> 40–49 | I8: 2752 | J8: =IF('Base tratada'!$K8=1,"Divorciado", IF('Base tratada'!$L8=1,"Casado", IF('Base tratada'!$M8=1, "Solteiro", IF('Base tratada'!$N8=1,"Juntos", "Viúvo")))) -> Divorciado | K8: 1 | L8: 0 | M8: 0 | N8: 0 | O8: 0 | P8: 0 | Q8: 0 | R8: 1 | S8: 0 | T8: 0 | U8: 235 | V8: 65 | W8: 164 | X8: 50 | Y8: 49 | Z8: 27 | AA8: 4 | AB8: 6 | AC8: 7 | AD8: 3 | AE8: 7 | AF8: ='Base tratada'!$AC8+'Base tratada'!$AD8+'Base tratada'!$AE8 -> 17 | AG8: =IF(Tabela3[[#This Row],[Total de Compras]]=0,"0", IF(Tabela3[[#This Row],[Total de Compras]]<=4,"1–4", IF(Tabela3[[#This Row],[Total de Compras]]<=10,"5–10", IF(Tabela3[[#This Row],[Total de Compras]]<=15,"11–15", IF(Tabela3[[#This Row],[Total de Compras]]<=20,"16–20", "+20"))))) -> 16–20 | AH8: =IF('Base tratada'!$AC8>=MAX('Base tratada'!$AD8,'Base tratada'!$AE8),"Web", IF('Base tratada'!$AD8>='Base tratada'!$AE8,"Catalog", "Store")) -> Web | AI8: =IF('Base tratada'!$AF8=0,"0",'Base tratada'!$AK8/'Base tratada'!$AF8) -> 33.117647 | AJ8: =IF('Base tratada'!$AI8=0,"R$ 0", IF('Base tratada'!$AI8<=25,"R$ 1–25", IF('Base tratada'!$AI8<=50,"R$ 26–50", "+R$ 50"))) -> R$ 26–50 | AK8: 563 | AL8: =IF('Base tratada'!$AK8<=100,"R$ 0-100", IF('Base tratada'!$AK8<=500,"R$ 101-500", IF('Base tratada'!$AK8<=1000,"R$ 501-1000", IF('Base tratada'!$AK8<=1500,"R$ 1001-1500", "+R$ 1500")))) -> R$ 501-1000 | AM8: 0 | AN8: 0 | AO8: 0 | AP8: 0 | AQ8: 0 | AR8: 0 | AS8: 0 | AT8: 3 | AU8: 11 | AV8: 536 | AW8: 0 | AX8: =IF(Tabela3[[#This Row],[Response]]=1, "Aceitou", "Não aceitou") -> Não aceitou | AY8: =Tabela3[[#This Row],[Faixa Recência]] & " | " & Tabela3[[#This Row],[Faixa Gasto]] & " | " & Tabela3[[#This Row],[Faixa ticket médio]] -> 31-45 dias | R$ 501-1000 | R$ 26–50 | AZ8: =IF(OR( AND(Tabela3[[#This Row],[Recency]]<=30,Tabela3[[#This Row],[MntTotal]]>=1000,Tabela3[[#This Row],[MntTotal]]>=50), AND(AND(Tabela3[[#This Row],[Recency]]>30,Tabela3[[#This Row],[Recency]]<=45), OR(Tabela3[[#This Row],[MntTotal]]>=1500,Tabela3[[#This Row],[Ticket médio]]>=50)) ),"SIM","NÃO") -> NÃO | BC8: target
A9: 8 | B9: 33454 | C9: 1 | D9: 0 | E9: 32 | F9: =IF('Base tratada'!$E9<=15,"0-15 dias", IF('Base tratada'!$E9<=30, "16-30 dias", IF('Base tratada'!$E9<=45, "31-45 dias", IF('Base tratada'!$E9<=60, "46-60 dias", IF('Base tratada'!$E9<=75, "61-75 dias", "76-99 dias"))))) -> 31-45 dias | G9: 35 | H9: =IF('Base tratada'!$G9<=29,"24–29", IF('Base tratada'!$G9<=39,"30–39", IF('Base tratada'!$G9<=49,"40–49", IF('Base tratada'!$G9<=59,"50–59", IF('Base tratada'!$G9<=69,"60–69", "70–80"))))) -> 30–39 | I9: 2576 | J9: =IF('Base tratada'!$K9=1,"Divorciado", IF('Base tratada'!$L9=1,"Casado", IF('Base tratada'!$M9=1, "Solteiro", IF('Base tratada'!$N9=1,"Juntos", "Viúvo")))) -> Casado | K9: 0 | L9: 1 | M9: 0 | N9: 0 | O9: 0 | P9: 0 | Q9: 0 | R9: 0 | S9: 0 | T9: 1 | U9: 76 | V9: 10 | W9: 56 | X9: 3 | Y9: 1 | Z9: 23 | AA9: 2 | AB9: 8 | AC9: 4 | AD9: 0 | AE9: 4 | AF9: ='Base tratada'!$AC9+'Base tratada'!$AD9+'Base tratada'!$AE9 -> 8 | AG9: =IF(Tabela3[[#This Row],[Total de Compras]]=0,"0", IF(Tabela3[[#This Row],[Total de Compras]]<=4,"1–4", IF(Tabela3[[#This Row],[Total de Compras]]<=10,"5–10", IF(Tabela3[[#This Row],[Total de Compras]]<=15,"11–15", IF(Tabela3[[#This Row],[Total de Compras]]<=20,"16–20", "+20"))))) -> 5–10 | AH9: =IF('Base tratada'!$AC9>=MAX('Base tratada'!$AD9,'Base tratada'!$AE9),"Web", IF('Base tratada'!$AD9>='Base tratada'!$AE9,"Catalog", "Store")) -> Web | AI9: =IF('Base tratada'!$AF9=0,"0",'Base tratada'!$AK9/'Base tratada'!$AF9) -> 18.25 | AJ9: =IF('Base tratada'!$AI9=0,"R$ 0", IF('Base tratada'!$AI9<=25,"R$ 1–25", IF('Base tratada'!$AI9<=50,"R$ 26–50", "+R$ 50"))) -> R$ 1–25 | AK9: 146 | AL9: =IF('Base tratada'!$AK9<=100,"R$ 0-100", IF('Base tratada'!$AK9<=500,"R$ 101-500", IF('Base tratada'!$AK9<=1000,"R$ 501-1000", IF('Base tratada'!$AK9<=1500,"R$ 1001-1500", "+R$ 1500")))) -> R$ 101-500 | AM9: 0 | AN9: 0 | AO9: 0 | AP9: 0 | AQ9: 0 | AR9: 0 | AS9: 0 | AT9: 3 | AU9: 11 | AV9: 123 | AW9: 0 | AX9: =IF(Tabela3[[#This Row],[Response]]=1, "Aceitou", "Não aceitou") -> Não aceitou | AY9: =Tabela3[[#This Row],[Faixa Recência]] & " | " & Tabela3[[#This Row],[Faixa Gasto]] & " | " & Tabela3[[#This Row],[Faixa ticket médio]] -> 31-45 dias | R$ 101-500 | R$ 1–25 | AZ9: =IF(OR( AND(Tabela3[[#This Row],[Recency]]<=30,Tabela3[[#This Row],[MntTotal]]>=1000,Tabela3[[#This Row],[MntTotal]]>=50), AND(AND(Tabela3[[#This Row],[Recency]]>30,Tabela3[[#This Row],[Recency]]<=45), OR(Tabela3[[#This Row],[MntTotal]]>=1500,Tabela3[[#This Row],[Ticket médio]]>=50)) ),"SIM","NÃO") -> NÃO | BC9: colunas criadas
A10: 9 | B10: 30351 | C10: 1 | D10: 0 | E10: 19 | F10: =IF('Base tratada'!$E10<=15,"0-15 dias", IF('Base tratada'!$E10<=30, "16-30 dias", IF('Base tratada'!$E10<=45, "31-45 dias", IF('Base tratada'!$E10<=60, "46-60 dias", IF('Base tratada'!$E10<=75, "61-75 dias", "76-99 dias"))))) -> 16-30 dias | G10: 46 | H10: =IF('Base tratada'!$G10<=29,"24–29", IF('Base tratada'!$G10<=39,"30–39", IF('Base tratada'!$G10<=49,"40–49", IF('Base tratada'!$G10<=59,"50–59", IF('Base tratada'!$G10<=69,"60–69", "70–80"))))) -> 40–49 | I10: 2547 | J10: =IF('Base tratada'!$K10=1,"Divorciado", IF('Base tratada'!$L10=1,"Casado", IF('Base tratada'!$M10=1, "Solteiro", IF('Base tratada'!$N10=1,"Juntos", "Viúvo")))) -> Juntos | K10: 0 | L10: 0 | M10: 0 | N10: 1 | O10: 0 | P10: 0 | Q10: 0 | R10: 0 | S10: 0 | T10: 1 | U10: 14 | V10: 0 | W10: 24 | X10: 3 | Y10: 3 | Z10: 2 | AA10: 1 | AB10: 9 | AC10: 3 | AD10: 0 | AE10: 2 | AF10: ='Base tratada'!$AC10+'Base tratada'!$AD10+'Base tratada'!$AE10 -> 5 | AG10: =IF(Tabela3[[#This Row],[Total de Compras]]=0,"0", IF(Tabela3[[#This Row],[Total de Compras]]<=4,"1–4", IF(Tabela3[[#This Row],[Total de Compras]]<=10,"5–10", IF(Tabela3[[#This Row],[Total de Compras]]<=15,"11–15", IF(Tabela3[[#This Row],[Total de Compras]]<=20,"16–20", "+20"))))) -> 5–10 | AH10: =IF('Base tratada'!$AC10>=MAX('Base tratada'!$AD10,'Base tratada'!$AE10),"Web", IF('Base tratada'!$AD10>='Base tratada'!$AE10,"Catalog", "Store")) -> Web | AI10: =IF('Base tratada'!$AF10=0,"0",'Base tratada'!$AK10/'Base tratada'!$AF10) -> 8.8 | AJ10: =IF('Base tratada'!$AI10=0,"R$ 0", IF('Base tratada'!$AI10<=25,"R$ 1–25", IF('Base tratada'!$AI10<=50,"R$ 26–50", "+R$ 50"))) -> R$ 1–25 | AK10: 44 | AL10: =IF('Base tratada'!$AK10<=100,"R$ 0-100", IF('Base tratada'!$AK10<=500,"R$ 101-500", IF('Base tratada'!$AK10<=1000,"R$ 501-1000", IF('Base tratada'!$AK10<=1500,"R$ 1001-1500", "+R$ 1500")))) -> R$ 0-100 | AM10: 0 | AN10: 0 | AO10: 0 | AP10: 0 | AQ10: 0 | AR10: 0 | AS10: 0 | AT10: 3 | AU10: 11 | AV10: 42 | AW10: 1 | AX10: =IF(Tabela3[[#This Row],[Response]]=1, "Aceitou", "Não aceitou") -> Aceitou | AY10: =Tabela3[[#This Row],[Faixa Recência]] & " | " & Tabela3[[#This Row],[Faixa Gasto]] & " | " & Tabela3[[#This Row],[Faixa ticket médio]] -> 16-30 dias | R$ 0-100 | R$ 1–25 | AZ10: =IF(OR( AND(Tabela3[[#This Row],[Recency]]<=30,Tabela3[[#This Row],[MntTotal]]>=1000,Tabela3[[#This Row],[MntTotal]]>=50), AND(AND(Tabela3[[#This Row],[Recency]]>30,Tabela3[[#This Row],[Recency]]<=45), OR(Tabela3[[#This Row],[MntTotal]]>=1500,Tabela3[[#This Row],[Ticket médio]]>=50)) ),"SIM","NÃO") -> NÃO | BC10: variável de segmentação
A11: 10 | B11: 5648 | C11: 1 | D11: 1 | E11: 68 | F11: =IF('Base tratada'!$E11<=15,"0-15 dias", IF('Base tratada'!$E11<=30, "16-30 dias", IF('Base tratada'!$E11<=45, "31-45 dias", IF('Base tratada'!$E11<=60, "46-60 dias", IF('Base tratada'!$E11<=75, "61-75 dias", "76-99 dias"))))) -> 61-75 dias | G11: 70 | H11: =IF('Base tratada'!$G11<=29,"24–29", IF('Base tratada'!$G11<=39,"30–39", IF('Base tratada'!$G11<=49,"40–49", IF('Base tratada'!$G11<=59,"50–59", IF('Base tratada'!$G11<=69,"60–69", "70–80"))))) -> 70–80 | I11: 2267 | J11: =IF('Base tratada'!$K11=1,"Divorciado", IF('Base tratada'!$L11=1,"Casado", IF('Base tratada'!$M11=1, "Solteiro", IF('Base tratada'!$N11=1,"Juntos", "Viúvo")))) -> Juntos | K11: 0 | L11: 0 | M11: 0 | N11: 1 | O11: 0 | P11: 0 | Q11: 0 | R11: 0 | S11: 0 | T11: 1 | U11: 28 | V11: 0 | W11: 6 | X11: 1 | Y11: 1 | Z11: 13 | AA11: 1 | AB11: 20 | AC11: 1 | AD11: 0 | AE11: 0 | AF11: ='Base tratada'!$AC11+'Base tratada'!$AD11+'Base tratada'!$AE11 -> 1 | AG11: =IF(Tabela3[[#This Row],[Total de Compras]]=0,"0", IF(Tabela3[[#This Row],[Total de Compras]]<=4,"1–4", IF(Tabela3[[#This Row],[Total de Compras]]<=10,"5–10", IF(Tabela3[[#This Row],[Total de Compras]]<=15,"11–15", IF(Tabela3[[#This Row],[Total de Compras]]<=20,"16–20", "+20"))))) -> 1–4 | AH11: =IF('Base tratada'!$AC11>=MAX('Base tratada'!$AD11,'Base tratada'!$AE11),"Web", IF('Base tratada'!$AD11>='Base tratada'!$AE11,"Catalog", "Store")) -> Web | AI11: =IF('Base tratada'!$AF11=0,"0",'Base tratada'!$AK11/'Base tratada'!$AF11) -> 36 | AJ11: =IF('Base tratada'!$AI11=0,"R$ 0", IF('Base tratada'!$AI11<=25,"R$ 1–25", IF('Base tratada'!$AI11<=50,"R$ 26–50", "+R$ 50"))) -> R$ 26–50 | AK11: 36 | AL11: =IF('Base tratada'!$AK11<=100,"R$ 0-100", IF('Base tratada'!$AK11<=500,"R$ 101-500", IF('Base tratada'!$AK11<=1000,"R$ 501-1000", IF('Base tratada'!$AK11<=1500,"R$ 1001-1500", "+R$ 1500")))) -> R$ 0-100 | AM11: 0 | AN11: 0 | AO11: 1 | AP11: 0 | AQ11: 0 | AR11: 1 | AS11: 0 | AT11: 3 | AU11: 11 | AV11: 23 | AW11: 0 | AX11: =IF(Tabela3[[#This Row],[Response]]=1, "Aceitou", "Não aceitou") -> Não aceitou | AY11: =Tabela3[[#This Row],[Faixa Recência]] & " | " & Tabela3[[#This Row],[Faixa Gasto]] & " | " & Tabela3[[#This Row],[Faixa ticket médio]] -> 61-75 dias | R$ 0-100 | R$ 26–50 | AZ11: =IF(OR( AND(Tabela3[[#This Row],[Recency]]<=30,Tabela3[[#This Row],[MntTotal]]>=1000,Tabela3[[#This Row],[MntTotal]]>=50), AND(AND(Tabela3[[#This Row],[Recency]]>30,Tabela3[[#This Row],[Recency]]<=45), OR(Tabela3[[#This Row],[MntTotal]]>=1500,Tabela3[[#This Row],[Ticket médio]]>=50)) ),"SIM","NÃO") -> NÃO
A12: 11 | B12: 7500 | C12: 0 | D12: 0 | E12: 59 | F12: =IF('Base tratada'!$E12<=15,"0-15 dias", IF('Base tratada'!$E12<=30, "16-30 dias", IF('Base tratada'!$E12<=45, "31-45 dias", IF('Base tratada'!$E12<=60, "46-60 dias", IF('Base tratada'!$E12<=75, "61-75 dias", "76-99 dias"))))) -> 46-60 dias | G12: 44 | H12: =IF('Base tratada'!$G12<=29,"24–29", IF('Base tratada'!$G12<=39,"30–39", IF('Base tratada'!$G12<=49,"40–49", IF('Base tratada'!$G12<=59,"50–59", IF('Base tratada'!$G12<=69,"60–69", "70–80"))))) -> 40–49 | I12: 2752 | J12: =IF('Base tratada'!$K12=1,"Divorciado", IF('Base tratada'!$L12=1,"Casado", IF('Base tratada'!$M12=1, "Solteiro", IF('Base tratada'!$N12=1,"Juntos", "Viúvo")))) -> Casado | K12: 0 | L12: 1 | M12: 0 | N12: 0 | O12: 0 | P12: 0 | Q12: 1 | R12: 0 | S12: 0 | T12: 0 | U12: 6 | V12: 16 | W12: 11 | X12: 11 | Y12: 1 | Z12: 16 | AA12: 1 | AB12: 8 | AC12: 2 | AD12: 0 | AE12: 3 | AF12: ='Base tratada'!$AC12+'Base tratada'!$AD12+'Base tratada'!$AE12 -> 5 | AG12: =IF(Tabela3[[#This Row],[Total de Compras]]=0,"0", IF(Tabela3[[#This Row],[Total de Compras]]<=4,"1–4", IF(Tabela3[[#This Row],[Total de Compras]]<=10,"5–10", IF(Tabela3[[#This Row],[Total de Compras]]<=15,"11–15", IF(Tabela3[[#This Row],[Total de Compras]]<=20,"16–20", "+20"))))) -> 5–10 | AH12: =IF('Base tratada'!$AC12>=MAX('Base tratada'!$AD12,'Base tratada'!$AE12),"Web", IF('Base tratada'!$AD12>='Base tratada'!$AE12,"Catalog", "Store")) -> Store | AI12: =IF('Base tratada'!$AF12=0,"0",'Base tratada'!$AK12/'Base tratada'!$AF12) -> 9 | AJ12: =IF('Base tratada'!$AI12=0,"R$ 0", IF('Base tratada'!$AI12<=25,"R$ 1–25", IF('Base tratada'!$AI12<=50,"R$ 26–50", "+R$ 50"))) -> R$ 1–25 | AK12: 45 | AL12: =IF('Base tratada'!$AK12<=100,"R$ 0-100", IF('Base tratada'!$AK12<=500,"R$ 101-500", IF('Base tratada'!$AK12<=1000,"R$ 501-1000", IF('Base tratada'!$AK12<=1500,"R$ 1001-1500", "+R$ 1500")))) -> R$ 0-100 | AM12: 0 | AN12: 0 | AO12: 0 | AP12: 0 | AQ12: 0 | AR12: 0 | AS12: 0 | AT12: 3 | AU12: 11 | AV12: 29 | AW12: 0 | AX12: =IF(Tabela3[[#This Row],[Response]]=1, "Aceitou", "Não aceitou") -> Não aceitou | AY12: =Tabela3[[#This Row],[Faixa Recência]] & " | " & Tabela3[[#This Row],[Faixa Gasto]] & " | " & Tabela3[[#This Row],[Faixa ticket médio]] -> 46-60 dias | R$ 0-100 | R$ 1–25 | AZ12: =IF(OR( AND(Tabela3[[#This Row],[Recency]]<=30,Tabela3[[#This Row],[MntTotal]]>=1000,Tabela3[[#This Row],[MntTotal]]>=50), AND(AND(Tabela3[[#This Row],[Recency]]>30,Tabela3[[#This Row],[Recency]]<=45), OR(Tabela3[[#This Row],[MntTotal]]>=1500,Tabela3[[#This Row],[Ticket médio]]>=50)) ),"SIM","NÃO") -> NÃO
A13: 12 | B13: 63033 | C13: 0 | D13: 0 | E13: 82 | F13: =IF('Base tratada'!$E13<=15,"0-15 dias", IF('Base tratada'!$E13<=30, "16-30 dias", IF('Base tratada'!$E13<=45, "31-45 dias", IF('Base tratada'!$E13<=60, "46-60 dias", IF('Base tratada'!$E13<=75, "61-75 dias", "76-99 dias"))))) -> 76-99 dias | G13: 61 | H13: =IF('Base tratada'!$G13<=29,"24–29", IF('Base tratada'!$G13<=39,"30–39", IF('Base tratada'!$G13<=49,"40–49", IF('Base tratada'!$G13<=59,"50–59", IF('Base tratada'!$G13<=69,"60–69", "70–80"))))) -> 60–69 | I13: 2385 | J13: =IF('Base tratada'!$K13=1,"Divorciado", IF('Base tratada'!$L13=1,"Casado", IF('Base tratada'!$M13=1, "Solteiro", IF('Base tratada'!$N13=1,"Juntos", "Viúvo")))) -> Divorciado | K13: 1 | L13: 0 | M13: 0 | N13: 0 | O13: 0 | P13: 0 | Q13: 0 | R13: 1 | S13: 0 | T13: 0 | U13: 194 | V13: 61 | W13: 480 | X13: 225 | Y13: 112 | Z13: 30 | AA13: 1 | AB13: 2 | AC13: 3 | AD13: 4 | AE13: 8 | AF13: ='Base tratada'!$AC13+'Base tratada'!$AD13+'Base tratada'!$AE13 -> 15 | AG13: =IF(Tabela3[[#This Row],[Total de Compras]]=0,"0", IF(Tabela3[[#This Row],[Total de Compras]]<=4,"1–4", IF(Tabela3[[#This Row],[Total de Compras]]<=10,"5–10", IF(Tabela3[[#This Row],[Total de Compras]]<=15,"11–15", IF(Tabela3[[#This Row],[Total de Compras]]<=20,"16–20", "+20"))))) -> 11–15 | AH13: =IF('Base tratada'!$AC13>=MAX('Base tratada'!$AD13,'Base tratada'!$AE13),"Web", IF('Base tratada'!$AD13>='Base tratada'!$AE13,"Catalog", "Store")) -> Store | AI13: =IF('Base tratada'!$AF13=0,"0",'Base tratada'!$AK13/'Base tratada'!$AF13) -> 71.466667 | AJ13: =IF('Base tratada'!$AI13=0,"R$ 0", IF('Base tratada'!$AI13<=25,"R$ 1–25", IF('Base tratada'!$AI13<=50,"R$ 26–50", "+R$ 50"))) -> +R$ 50 | AK13: 1072 | AL13: =IF('Base tratada'!$AK13<=100,"R$ 0-100", IF('Base tratada'!$AK13<=500,"R$ 101-500", IF('Base tratada'!$AK13<=1000,"R$ 501-1000", IF('Base tratada'!$AK13<=1500,"R$ 1001-1500", "+R$ 1500")))) -> R$ 1001-1500 | AM13: 0 | AN13: 0 | AO13: 0 | AP13: 0 | AQ13: 0 | AR13: 0 | AS13: 0 | AT13: 3 | AU13: 11 | AV13: 1042 | AW13: 0 | AX13: =IF(Tabela3[[#This Row],[Response]]=1, "Aceitou", "Não aceitou") -> Não aceitou | AY13: =Tabela3[[#This Row],[Faixa Recência]] & " | " & Tabela3[[#This Row],[Faixa Gasto]] & " | " & Tabela3[[#This Row],[Faixa ticket médio]] -> 76-99 dias | R$ 1001-1500 | +R$ 50 | AZ13: =IF(OR( AND(Tabela3[[#This Row],[Recency]]<=30,Tabela3[[#This Row],[MntTotal]]>=1000,Tabela3[[#This Row],[MntTotal]]>=50), AND(AND(Tabela3[[#This Row],[Recency]]>30,Tabela3[[#This Row],[Recency]]<=45), OR(Tabela3[[#This Row],[MntTotal]]>=1500,Tabela3[[#This Row],[Ticket médio]]>=50)) ),"SIM","NÃO") -> NÃO
A14: 13 | B14: 59354 | C14: 1 | D14: 1 | E14: 53 | F14: =IF('Base tratada'!$E14<=15,"0-15 dias", IF('Base tratada'!$E14<=30, "16-30 dias", IF('Base tratada'!$E14<=45, "31-45 dias", IF('Base tratada'!$E14<=60, "46-60 dias", IF('Base tratada'!$E14<=75, "61-75 dias", "76-99 dias"))))) -> 46-60 dias | G14: 68 | H14: =IF('Base tratada'!$G14<=29,"24–29", IF('Base tratada'!$G14<=39,"30–39", IF('Base tratada'!$G14<=49,"40–49", IF('Base tratada'!$G14<=59,"50–59", IF('Base tratada'!$G14<=69,"60–69", "70–80"))))) -> 60–69 | I14: 2385 | J14: =IF('Base tratada'!$K14=1,"Divorciado", IF('Base tratada'!$L14=1,"Casado", IF('Base tratada'!$M14=1, "Solteiro", IF('Base tratada'!$N14=1,"Juntos", "Viúvo")))) -> Divorciado | K14: 1 | L14: 0 | M14: 0 | N14: 0 | O14: 0 | P14: 0 | Q14: 0 | R14: 0 | S14: 1 | T14: 0 | U14: 233 | V14: 2 | W14: 53 | X14: 3 | Y14: 5 | Z14: 14 | AA14: 3 | AB14: 6 | AC14: 6 | AD14: 1 | AE14: 5 | AF14: ='Base tratada'!$AC14+'Base tratada'!$AD14+'Base tratada'!$AE14 -> 12 | AG14: =IF(Tabela3[[#This Row],[Total de Compras]]=0,"0", IF(Tabela3[[#This Row],[Total de Compras]]<=4,"1–4", IF(Tabela3[[#This Row],[Total de Compras]]<=10,"5–10", IF(Tabela3[[#This Row],[Total de Compras]]<=15,"11–15", IF(Tabela3[[#This Row],[Total de Compras]]<=20,"16–20", "+20"))))) -> 11–15 | AH14: =IF('Base tratada'!$AC14>=MAX('Base tratada'!$AD14,'Base tratada'!$AE14),"Web", IF('Base tratada'!$AD14>='Base tratada'!$AE14,"Catalog", "Store")) -> Web | AI14: =IF('Base tratada'!$AF14=0,"0",'Base tratada'!$AK14/'Base tratada'!$AF14) -> 24.666667 | AJ14: =IF('Base tratada'!$AI14=0,"R$ 0", IF('Base tratada'!$AI14<=25,"R$ 1–25", IF('Base tratada'!$AI14<=50,"R$ 26–50", "+R$ 50"))) -> R$ 1–25 | AK14: 296 | AL14: =IF('Base tratada'!$AK14<=100,"R$ 0-100", IF('Base tratada'!$AK14<=500,"R$ 101-500", IF('Base tratada'!$AK14<=1000,"R$ 501-1000", IF('Base tratada'!$AK14<=1500,"R$ 1001-1500", "+R$ 1500")))) -> R$ 101-500 | AM14: 0 | AN14: 0 | AO14: 0 | AP14: 0 | AQ14: 0 | AR14: 0 | AS14: 0 | AT14: 3 | AU14: 11 | AV14: 282 | AW14: 0 | AX14: =IF(Tabela3[[#This Row],[Response]]=1, "Aceitou", "Não aceitou") -> Não aceitou | AY14: =Tabela3[[#This Row],[Faixa Recência]] & " | " & Tabela3[[#This Row],[Faixa Gasto]] & " | " & Tabela3[[#This Row],[Faixa ticket médio]] -> 46-60 dias | R$ 101-500 | R$ 1–25 | AZ14: =IF(OR( AND(Tabela3[[#This Row],[Recency]]<=30,Tabela3[[#This Row],[MntTotal]]>=1000,Tabela3[[#This Row],[MntTotal]]>=50), AND(AND(Tabela3[[#This Row],[Recency]]>30,Tabela3[[#This Row],[Recency]]<=45), OR(Tabela3[[#This Row],[MntTotal]]>=1500,Tabela3[[#This Row],[Ticket médio]]>=50)) ),"SIM","NÃO") -> NÃO
A15: 14 | B15: 17323 | C15: 0 | D15: 0 | E15: 38 | F15: =IF('Base tratada'!$E15<=15,"0-15 dias", IF('Base tratada'!$E15<=30, "16-30 dias", IF('Base tratada'!$E15<=45, "31-45 dias", IF('Base tratada'!$E15<=60, "46-60 dias", IF('Base tratada'!$E15<=75, "61-75 dias", "76-99 dias"))))) -> 31-45 dias | G15: 33 | H15: =IF('Base tratada'!$G15<=29,"24–29", IF('Base tratada'!$G15<=39,"30–39", IF('Base tratada'!$G15<=49,"40–49", IF('Base tratada'!$G15<=59,"50–59", IF('Base tratada'!$G15<=69,"60–69", "70–80"))))) -> 30–39 | I15: 2786 | J15: =IF('Base tratada'!$K15=1,"Divorciado", IF('Base tratada'!$L15=1,"Casado", IF('Base tratada'!$M15=1, "Solteiro", IF('Base tratada'!$N15=1,"Juntos", "Viúvo")))) -> Casado | K15: 0 | L15: 1 | M15: 0 | N15: 0 | O15: 0 | P15: 0 | Q15: 0 | R15: 1 | S15: 0 | T15: 0 | U15: 3 | V15: 14 | W15: 17 | X15: 6 | Y15: 1 | Z15: 5 | AA15: 1 | AB15: 8 | AC15: 1 | AD15: 0 | AE15: 3 | AF15: ='Base tratada'!$AC15+'Base tratada'!$AD15+'Base tratada'!$AE15 -> 4 | AG15: =IF(Tabela3[[#This Row],[Total de Compras]]=0,"0", IF(Tabela3[[#This Row],[Total de Compras]]<=4,"1–4", IF(Tabela3[[#This Row],[Total de Compras]]<=10,"5–10", IF(Tabela3[[#This Row],[Total de Compras]]<=15,"11–15", IF(Tabela3[[#This Row],[Total de Compras]]<=20,"16–20", "+20"))))) -> 1–4 | AH15: =IF('Base tratada'!$AC15>=MAX('Base tratada'!$AD15,'Base tratada'!$AE15),"Web", IF('Base tratada'!$AD15>='Base tratada'!$AE15,"Catalog", "Store")) -> Store | AI15: =IF('Base tratada'!$AF15=0,"0",'Base tratada'!$AK15/'Base tratada'!$AF15) -> 10.25 | AJ15: =IF('Base tratada'!$AI15=0,"R$ 0", IF('Base tratada'!$AI15<=25,"R$ 1–25", IF('Base tratada'!$AI15<=50,"R$ 26–50", "+R$ 50"))) -> R$ 1–25 | AK15: 41 | AL15: =IF('Base tratada'!$AK15<=100,"R$ 0-100", IF('Base tratada'!$AK15<=500,"R$ 101-500", IF('Base tratada'!$AK15<=1000,"R$ 501-1000", IF('Base tratada'!$AK15<=1500,"R$ 1001-1500", "+R$ 1500")))) -> R$ 0-100 | AM15: 0 | AN15: 0 | AO15: 0 | AP15: 0 | AQ15: 0 | AR15: 0 | AS15: 0 | AT15: 3 | AU15: 11 | AV15: 36 | AW15: 0 | AX15: =IF(Tabela3[[#This Row],[Response]]=1, "Aceitou", "Não aceitou") -> Não aceitou | AY15: =Tabela3[[#This Row],[Faixa Recência]] & " | " & Tabela3[[#This Row],[Faixa Gasto]] & " | " & Tabela3[[#This Row],[Faixa ticket médio]] -> 31-45 dias | R$ 0-100 | R$ 1–25 | AZ15: =IF(OR( AND(Tabela3[[#This Row],[Recency]]<=30,Tabela3[[#This Row],[MntTotal]]>=1000,Tabela3[[#This Row],[MntTotal]]>=50), AND(AND(Tabela3[[#This Row],[Recency]]>30,Tabela3[[#This Row],[Recency]]<=45), OR(Tabela3[[#This Row],[MntTotal]]>=1500,Tabela3[[#This Row],[Ticket médio]]>=50)) ),"SIM","NÃO") -> NÃO
A16: 15 | B16: 82800 | C16: 0 | D16: 0 | E16: 23 | F16: =IF('Base tratada'!$E16<=15,"0-15 dias", IF('Base tratada'!$E16<=30, "16-30 dias", IF('Base tratada'!$E16<=45, "31-45 dias", IF('Base tratada'!$E16<=60, "46-60 dias", IF('Base tratada'!$E16<=75, "61-75 dias", "76-99 dias"))))) -> 16-30 dias | G16: 74 | H16: =IF('Base tratada'!$G16<=29,"24–29", IF('Base tratada'!$G16<=39,"30–39", IF('Base tratada'!$G16<=49,"40–49", IF('Base tratada'!$G16<=59,"50–59", IF('Base tratada'!$G16<=69,"60–69", "70–80"))))) -> 70–80 | I16: 2741 | J16: =IF('Base tratada'!$K16=1,"Divorciado", IF('Base tratada'!$L16=1,"Casado", IF('Base tratada'!$M16=1, "Solteiro", IF('Base tratada'!$N16=1,"Juntos", "Viúvo")))) -> Solteiro | K16: 0 | L16: 0 | M16: 1 | N16: 0 | O16: 0 | P16: 0 | Q16: 0 | R16: 0 | S16: 0 | T16: 1 | U16: 1006 | V16: 22 | W16: 115 | X16: 59 | Y16: 68 | Z16: 45 | AA16: 1 | AB16: 3 | AC16: 7 | AD16: 6 | AE16: 12 | AF16: ='Base tratada'!$AC16+'Base tratada'!$AD16+'Base tratada'!$AE16 -> 25 | AG16: =IF(Tabela3[[#This Row],[Total de Compras]]=0,"0", IF(Tabela3[[#This Row],[Total de Compras]]<=4,"1–4", IF(Tabela3[[#This Row],[Total de Compras]]<=10,"5–10", IF(Tabela3[[#This Row],[Total de Compras]]<=15,"11–15", IF(Tabela3[[#This Row],[Total de Compras]]<=20,"16–20", "+20"))))) -> +20 | AH16: =IF('Base tratada'!$AC16>=MAX('Base tratada'!$AD16,'Base tratada'!$AE16),"Web", IF('Base tratada'!$AD16>='Base tratada'!$AE16,"Catalog", "Store")) -> Store | AI16: =IF('Base tratada'!$AF16=0,"0",'Base tratada'!$AK16/'Base tratada'!$AF16) -> 50.8 | AJ16: =IF('Base tratada'!$AI16=0,"R$ 0", IF('Base tratada'!$AI16<=25,"R$ 1–25", IF('Base tratada'!$AI16<=50,"R$ 26–50", "+R$ 50"))) -> +R$ 50 | AK16: 1270 | AL16: =IF('Base tratada'!$AK16<=100,"R$ 0-100", IF('Base tratada'!$AK16<=500,"R$ 101-500", IF('Base tratada'!$AK16<=1000,"R$ 501-1000", IF('Base tratada'!$AK16<=1500,"R$ 1001-1500", "+R$ 1500")))) -> R$ 1001-1500 | AM16: 1 | AN16: 0 | AO16: 0 | AP16: 0 | AQ16: 1 | AR16: 2 | AS16: 0 | AT16: 3 | AU16: 11 | AV16: 1225 | AW16: 1 | AX16: =IF(Tabela3[[#This Row],[Response]]=1, "Aceitou", "Não aceitou") -> Aceitou | AY16: =Tabela3[[#This Row],[Faixa Recência]] & " | " & Tabela3[[#This Row],[Faixa Gasto]] & " | " & Tabela3[[#This Row],[Faixa ticket médio]] -> 16-30 dias | R$ 1001-1500 | +R$ 50 | AZ16: =IF(OR( AND(Tabela3[[#This Row],[Recency]]<=30,Tabela3[[#This Row],[MntTotal]]>=1000,Tabela3[[#This Row],[MntTotal]]>=50), AND(AND(Tabela3[[#This Row],[Recency]]>30,Tabela3[[#This Row],[Recency]]<=45), OR(Tabela3[[#This Row],[MntTotal]]>=1500,Tabela3[[#This Row],[Ticket médio]]>=50)) ),"SIM","NÃO") -> SIM
A17: 16 | B17: 41850 | C17: 1 | D17: 1 | E17: 51 | F17: =IF('Base tratada'!$E17<=15,"0-15 dias", IF('Base tratada'!$E17<=30, "16-30 dias", IF('Base tratada'!$E17<=45, "31-45 dias", IF('Base tratada'!$E17<=60, "46-60 dias", IF('Base tratada'!$E17<=75, "61-75 dias", "76-99 dias"))))) -> 46-60 dias | G17: 40 | H17: =IF('Base tratada'!$G17<=29,"24–29", IF('Base tratada'!$G17<=39,"30–39", IF('Base tratada'!$G17<=49,"40–49", IF('Base tratada'!$G17<=59,"50–59", IF('Base tratada'!$G17<=69,"60–69", "70–80"))))) -> 40–49 | I17: 2711 | J17: =IF('Base tratada'!$K17=1,"Divorciado", IF('Base tratada'!$L17=1,"Casado", IF('Base tratada'!$M17=1, "Solteiro", IF('Base tratada'!$N17=1,"Juntos", "Viúvo")))) -> Casado | K17: 0 | L17: 1 | M17: 0 | N17: 0 | O17: 0 | P17: 0 | Q17: 0 | R17: 1 | S17: 0 | T17: 0 | U17: 53 | V17: 5 | W17: 19 | X17: 2 | Y17: 13 | Z17: 4 | AA17: 3 | AB17: 8 | AC17: 3 | AD17: 0 | AE17: 3 | AF17: ='Base tratada'!$AC17+'Base tratada'!$AD17+'Base tratada'!$AE17 -> 6 | AG17: =IF(Tabela3[[#This Row],[Total de Compras]]=0,"0", IF(Tabela3[[#This Row],[Total de Compras]]<=4,"1–4", IF(Tabela3[[#This Row],[Total de Compras]]<=10,"5–10", IF(Tabela3[[#This Row],[Total de Compras]]<=15,"11–15", IF(Tabela3[[#This Row],[Total de Compras]]<=20,"16–20", "+20"))))) -> 5–10 | AH17: =IF('Base tratada'!$AC17>=MAX('Base tratada'!$AD17,'Base tratada'!$AE17),"Web", IF('Base tratada'!$AD17>='Base tratada'!$AE17,"Catalog", "Store")) -> Web | AI17: =IF('Base tratada'!$AF17=0,"0",'Base tratada'!$AK17/'Base tratada'!$AF17) -> 15.333333 | AJ17: =IF('Base tratada'!$AI17=0,"R$ 0", IF('Base tratada'!$AI17<=25,"R$ 1–25", IF('Base tratada'!$AI17<=50,"R$ 26–50", "+R$ 50"))) -> R$ 1–25 | AK17: 92 | AL17: =IF('Base tratada'!$AK17<=100,"R$ 0-100", IF('Base tratada'!$AK17<=500,"R$ 101-500", IF('Base tratada'!$AK17<=1000,"R$ 501-1000", IF('Base tratada'!$AK17<=1500,"R$ 1001-1500", "+R$ 1500")))) -> R$ 0-100 | AM17: 0 | AN17: 0 | AO17: 0 | AP17: 0 | AQ17: 0 | AR17: 0 | AS17: 0 | AT17: 3 | AU17: 11 | AV17: 88 | AW17: 0 | AX17: =IF(Tabela3[[#This Row],[Response]]=1, "Aceitou", "Não aceitou") -> Não aceitou | AY17: =Tabela3[[#This Row],[Faixa Recência]] & " | " & Tabela3[[#This Row],[Faixa Gasto]] & " | " & Tabela3[[#This Row],[Faixa ticket médio]] -> 46-60 dias | R$ 0-100 | R$ 1–25 | AZ17: =IF(OR( AND(Tabela3[[#This Row],[Recency]]<=30,Tabela3[[#This Row],[MntTotal]]>=1000,Tabela3[[#This Row],[MntTotal]]>=50), AND(AND(Tabela3[[#This Row],[Recency]]>30,Tabela3[[#This Row],[Recency]]<=45), OR(Tabela3[[#This Row],[MntTotal]]>=1500,Tabela3[[#This Row],[Ticket médio]]>=50)) ),"SIM","NÃO") -> NÃO
A18: 17 | B18: 37760 | C18: 0 | D18: 0 | E18: 20 | F18: =IF('Base tratada'!$E18<=15,"0-15 dias", IF('Base tratada'!$E18<=30, "16-30 dias", IF('Base tratada'!$E18<=45, "31-45 dias", IF('Base tratada'!$E18<=60, "46-60 dias", IF('Base tratada'!$E18<=75, "61-75 dias", "76-99 dias"))))) -> 16-30 dias | G18: 74 | H18: =IF('Base tratada'!$G18<=29,"24–29", IF('Base tratada'!$G18<=39,"30–39", IF('Base tratada'!$G18<=49,"40–49", IF('Base tratada'!$G18<=59,"50–59", IF('Base tratada'!$G18<=69,"60–69", "70–80"))))) -> 70–80 | I18: 2826 | J18: =IF('Base tratada'!$K18=1,"Divorciado", IF('Base tratada'!$L18=1,"Casado", IF('Base tratada'!$M18=1, "Solteiro", IF('Base tratada'!$N18=1,"Juntos", "Viúvo")))) -> Juntos | K18: 0 | L18: 0 | M18: 0 | N18: 1 | O18: 0 | P18: 0 | Q18: 0 | R18: 1 | S18: 0 | T18: 0 | U18: 84 | V18: 5 | W18: 38 | X18: 150 | Y18: 12 | Z18: 28 | AA18: 2 | AB18: 7 | AC18: 4 | AD18: 1 | AE18: 6 | AF18: ='Base tratada'!$AC18+'Base tratada'!$AD18+'Base tratada'!$AE18 -> 11 | AG18: =IF(Tabela3[[#This Row],[Total de Compras]]=0,"0", IF(Tabela3[[#This Row],[Total de Compras]]<=4,"1–4", IF(Tabela3[[#This Row],[Total de Compras]]<=10,"5–10", IF(Tabela3[[#This Row],[Total de Compras]]<=15,"11–15", IF(Tabela3[[#This Row],[Total de Compras]]<=20,"16–20", "+20"))))) -> 11–15 | AH18: =IF('Base tratada'!$AC18>=MAX('Base tratada'!$AD18,'Base tratada'!$AE18),"Web", IF('Base tratada'!$AD18>='Base tratada'!$AE18,"Catalog", "Store")) -> Store | AI18: =IF('Base tratada'!$AF18=0,"0",'Base tratada'!$AK18/'Base tratada'!$AF18) -> 26.272727 | AJ18: =IF('Base tratada'!$AI18=0,"R$ 0", IF('Base tratada'!$AI18<=25,"R$ 1–25", IF('Base tratada'!$AI18<=50,"R$ 26–50", "+R$ 50"))) -> R$ 26–50 | AK18: 289 | AL18: =IF('Base tratada'!$AK18<=100,"R$ 0-100", IF('Base tratada'!$AK18<=500,"R$ 101-500", IF('Base tratada'!$AK18<=1000,"R$ 501-1000", IF('Base tratada'!$AK18<=1500,"R$ 1001-1500", "+R$ 1500")))) -> R$ 101-500 | AM18: 0 | AN18: 0 | AO18: 0 | AP18: 0 | AQ18: 0 | AR18: 0 | AS18: 0 | AT18: 3 | AU18: 11 | AV18: 261 | AW18: 0 | AX18: =IF(Tabela3[[#This Row],[Response]]=1, "Aceitou", "Não aceitou") -> Não aceitou | AY18: =Tabela3[[#This Row],[Faixa Recência]] & " | " & Tabela3[[#This Row],[Faixa Gasto]] & " | " & Tabela3[[#This Row],[Faixa ticket médio]] -> 16-30 dias | R$ 101-500 | R$ 26–50 | AZ18: =IF(OR( AND(Tabela3[[#This Row],[Recency]]<=30,Tabela3[[#This Row],[MntTotal]]>=1000,Tabela3[[#This Row],[MntTotal]]>=50), AND(AND(Tabela3[[#This Row],[Recency]]>30,Tabela3[[#This Row],[Recency]]<=45), OR(Tabela3[[#This Row],[MntTotal]]>=1500,Tabela3[[#This Row],[Ticket médio]]>=50)) ),"SIM","NÃO") -> NÃO
A19: 18 | B19: 76995 | C19: 0 | D19: 1 | E19: 91 | F19: =IF('Base tratada'!$E19<=15,"0-15 dias", IF('Base tratada'!$E19<=30, "16-30 dias", IF('Base tratada'!$E19<=45, "31-45 dias", IF('Base tratada'!$E19<=60, "46-60 dias", IF('Base tratada'!$E19<=75, "61-75 dias", "76-99 dias"))))) -> 76-99 dias | G19: 71 | H19: =IF('Base tratada'!$G19<=29,"24–29", IF('Base tratada'!$G19<=39,"30–39", IF('Base tratada'!$G19<=49,"40–49", IF('Base tratada'!$G19<=59,"50–59", IF('Base tratada'!$G19<=69,"60–69", "70–80"))))) -> 70–80 | I19: 2617 | J19: =IF('Base tratada'!$K19=1,"Divorciado", IF('Base tratada'!$L19=1,"Casado", IF('Base tratada'!$M19=1, "Solteiro", IF('Base tratada'!$N19=1,"Juntos", "Viúvo")))) -> Casado | K19: 0 | L19: 1 | M19: 0 | N19: 0 | O19: 0 | P19: 0 | Q19: 0 | R19: 0 | S19: 1 | T19: 0 | U19: 1012 | V19: 80 | W19: 498 | X19: 0 | Y19: 16 | Z19: 176 | AA19: 2 | AB19: 5 | AC19: 11 | AD19: 4 | AE19: 9 | AF19: ='Base tratada'!$AC19+'Base tratada'!$AD19+'Base tratada'!$AE19 -> 24 | AG19: =IF(Tabela3[[#This Row],[Total de Compras]]=0,"0", IF(Tabela3[[#This Row],[Total de Compras]]<=4,"1–4", IF(Tabela3[[#This Row],[Total de Compras]]<=10,"5–10", IF(Tabela3[[#This Row],[Total de Compras]]<=15,"11–15", IF(Tabela3[[#This Row],[Total de Compras]]<=20,"16–20", "+20"))))) -> +20 | AH19: =IF('Base tratada'!$AC19>=MAX('Base tratada'!$AD19,'Base tratada'!$AE19),"Web", IF('Base tratada'!$AD19>='Base tratada'!$AE19,"Catalog", "Store")) -> Web | AI19: =IF('Base tratada'!$AF19=0,"0",'Base tratada'!$AK19/'Base tratada'!$AF19) -> 66.916667 | AJ19: =IF('Base tratada'!$AI19=0,"R$ 0", IF('Base tratada'!$AI19<=25,"R$ 1–25", IF('Base tratada'!$AI19<=50,"R$ 26–50", "+R$ 50"))) -> +R$ 50 | AK19: 1606 | AL19: =IF('Base tratada'!$AK19<=100,"R$ 0-100", IF('Base tratada'!$AK19<=500,"R$ 101-500", IF('Base tratada'!$AK19<=1000,"R$ 501-1000", IF('Base tratada'!$AK19<=1500,"R$ 1001-1500", "+R$ 1500")))) -> +R$ 1500 | AM19: 1 | AN19: 0 | AO19: 0 | AP19: 0 | AQ19: 0 | AR19: 1 | AS19: 0 | AT19: 3 | AU19: 11 | AV19: 1430 | AW19: 0 | AX19: =IF(Tabela3[[#This Row],[Response]]=1, "Aceitou", "Não aceitou") -> Não aceitou | AY19: =Tabela3[[#This Row],[Faixa Recência]] & " | " & Tabela3[[#This Row],[Faixa Gasto]] & " | " & Tabela3[[#This Row],[Faixa ticket médio]] -> 76-99 dias | +R$ 1500 | +R$ 50 | AZ19: =IF(OR( AND(Tabela3[[#This Row],[Recency]]<=30,Tabela3[[#This Row],[MntTotal]]>=1000,Tabela3[[#This Row],[MntTotal]]>=50), AND(AND(Tabela3[[#This Row],[Recency]]>30,Tabela3[[#This Row],[Recency]]<=45), OR(Tabela3[[#This Row],[MntTotal]]>=1500,Tabela3[[#This Row],[Ticket médio]]>=50)) ),"SIM","NÃO") -> NÃO
A20: 19 | B20: 33812 | C20: 1 | D20: 0 | E20: 86 | F20: =IF('Base tratada'!$E20<=15,"0-15 dias", IF('Base tratada'!$E20<=30, "16-30 dias", IF('Base tratada'!$E20<=45, "31-45 dias", IF('Base tratada'!$E20<=60, "46-60 dias", IF('Base tratada'!$E20<=75, "61-75 dias", "76-99 dias"))))) -> 76-99 dias | G20: 35 | H20: =IF('Base tratada'!$G20<=29,"24–29", IF('Base tratada'!$G20<=39,"30–39", IF('Base tratada'!$G20<=49,"40–49", IF('Base tratada'!$G20<=59,"50–59", IF('Base tratada'!$G20<=69,"60–69", "70–80"))))) -> 30–39 | I20: 2762 | J20: =IF('Base tratada'!$K20=1,"Divorciado", IF('Base tratada'!$L20=1,"Casado", IF('Base tratada'!$M20=1, "Solteiro", IF('Base tratada'!$N20=1,"Juntos", "Viúvo")))) -> Solteiro | K20: 0 | L20: 0 | M20: 1 | N20: 0 | O20: 0 | P20: 1 | Q20: 0 | R20: 0 | S20: 0 | T20: 0 | U20: 4 | V20: 17 | W20: 19 | X20: 30 | Y20: 24 | Z20: 39 | AA20: 2 | AB20: 6 | AC20: 2 | AD20: 1 | AE20: 3 | AF20: ='Base tratada'!$AC20+'Base tratada'!$AD20+'Base tratada'!$AE20 -> 6 | AG20: =IF(Tabela3[[#This Row],[Total de Compras]]=0,"0", IF(Tabela3[[#This Row],[Total de Compras]]<=4,"1–4", IF(Tabela3[[#This Row],[Total de Compras]]<=10,"5–10", IF(Tabela3[[#This Row],[Total de Compras]]<=15,"11–15", IF(Tabela3[[#This Row],[Total de Compras]]<=20,"16–20", "+20"))))) -> 5–10 | AH20: =IF('Base tratada'!$AC20>=MAX('Base tratada'!$AD20,'Base tratada'!$AE20),"Web", IF('Base tratada'!$AD20>='Base tratada'!$AE20,"Catalog", "Store")) -> Store | AI20: =IF('Base tratada'!$AF20=0,"0",'Base tratada'!$AK20/'Base tratada'!$AF20) -> 15.666667 | AJ20: =IF('Base tratada'!$AI20=0,"R$ 0", IF('Base tratada'!$AI20<=25,"R$ 1–25", IF('Base tratada'!$AI20<=50,"R$ 26–50", "+R$ 50"))) -> R$ 1–25 | AK20: 94 | AL20: =IF('Base tratada'!$AK20<=100,"R$ 0-100", IF('Base tratada'!$AK20<=500,"R$ 101-500", IF('Base tratada'!$AK20<=1000,"R$ 501-1000", IF('Base tratada'!$AK20<=1500,"R$ 1001-1500", "+R$ 1500")))) -> R$ 0-100 | AM20: 0 | AN20: 0 | AO20: 0 | AP20: 0 | AQ20: 0 | AR20: 0 | AS20: 0 | AT20: 3 | AU20: 11 | AV20: 55 | AW20: 0 | AX20: =IF(Tabela3[[#This Row],[Response]]=1, "Aceitou", "Não aceitou") -> Não aceitou | AY20: =Tabela3[[#This Row],[Faixa Recência]] & " | " & Tabela3[[#This Row],[Faixa Gasto]] & " | " & Tabela3[[#This Row],[Faixa ticket médio]] -> 76-99 dias | R$ 0-100 | R$ 1–25 | AZ20: =IF(OR( AND(Tabela3[[#This Row],[Recency]]<=30,Tabela3[[#This Row],[MntTotal]]>=1000,Tabela3[[#This Row],[MntTotal]]>=50), AND(AND(Tabela3[[#This Row],[Recency]]>30,Tabela3[[#This Row],[Recency]]<=45), OR(Tabela3[[#This Row],[MntTotal]]>=1500,Tabela3[[#This Row],[Ticket médio]]>=50)) ),"SIM","NÃO") -> NÃO
A21: 20 | B21: 37040 | C21: 0 | D21: 0 | E21: 41 | F21: =IF('Base tratada'!$E21<=15,"0-15 dias", IF('Base tratada'!$E21<=30, "16-30 dias", IF('Base tratada'!$E21<=45, "31-45 dias", IF('Base tratada'!$E21<=60, "46-60 dias", IF('Base tratada'!$E21<=75, "61-75 dias", "76-99 dias"))))) -> 31-45 dias | G21: 38 | H21: =IF('Base tratada'!$G21<=29,"24–29", IF('Base tratada'!$G21<=39,"30–39", IF('Base tratada'!$G21<=49,"40–49", IF('Base tratada'!$G21<=59,"50–59", IF('Base tratada'!$G21<=69,"60–69", "70–80"))))) -> 30–39 | I21: 2849 | J21: =IF('Base tratada'!$K21=1,"Divorciado", IF('Base tratada'!$L21=1,"Casado", IF('Base tratada'!$M21=1, "Solteiro", IF('Base tratada'!$N21=1,"Juntos", "Viúvo")))) -> Casado | K21: 0 | L21: 1 | M21: 0 | N21: 0 | O21: 0 | P21: 0 | Q21: 0 | R21: 1 | S21: 0 | T21: 0 | U21: 86 | V21: 2 | W21: 73 | X21: 69 | Y21: 38 | Z21: 48 | AA21: 1 | AB21: 8 | AC21: 4 | AD21: 2 | AE21: 5 | AF21: ='Base tratada'!$AC21+'Base tratada'!$AD21+'Base tratada'!$AE21 -> 11 | AG21: =IF(Tabela3[[#This Row],[Total de Compras]]=0,"0", IF(Tabela3[[#This Row],[Total de Compras]]<=4,"1–4", IF(Tabela3[[#This Row],[Total de Compras]]<=10,"5–10", IF(Tabela3[[#This Row],[Total de Compras]]<=15,"11–15", IF(Tabela3[[#This Row],[Total de Compras]]<=20,"16–20", "+20"))))) -> 11–15 | AH21: =IF('Base tratada'!$AC21>=MAX('Base tratada'!$AD21,'Base tratada'!$AE21),"Web", IF('Base tratada'!$AD21>='Base tratada'!$AE21,"Catalog", "Store")) -> Store | AI21: =IF('Base tratada'!$AF21=0,"0",'Base tratada'!$AK21/'Base tratada'!$AF21) -> 24.363636 | AJ21: =IF('Base tratada'!$AI21=0,"R$ 0", IF('Base tratada'!$AI21<=25,"R$ 1–25", IF('Base tratada'!$AI21<=50,"R$ 26–50", "+R$ 50"))) -> R$ 1–25 | AK21: 268 | AL21: =IF('Base tratada'!$AK21<=100,"R$ 0-100", IF('Base tratada'!$AK21<=500,"R$ 101-500", IF('Base tratada'!$AK21<=1000,"R$ 501-1000", IF('Base tratada'!$AK21<=1500,"R$ 1001-1500", "+R$ 1500")))) -> R$ 101-500 | AM21: 0 | AN21: 0 | AO21: 0 | AP21: 0 | AQ21: 0 | AR21: 0 | AS21: 0 | AT21: 3 | AU21: 11 | AV21: 220 | AW21: 0 | AX21: =IF(Tabela3[[#This Row],[Response]]=1, "Aceitou", "Não aceitou") -> Não aceitou | AY21: =Tabela3[[#This Row],[Faixa Recência]] & " | " & Tabela3[[#This Row],[Faixa Gasto]] & " | " & Tabela3[[#This Row],[Faixa ticket médio]] -> 31-45 dias | R$ 101-500 | R$ 1–25 | AZ21: =IF(OR( AND(Tabela3[[#This Row],[Recency]]<=30,Tabela3[[#This Row],[MntTotal]]>=1000,Tabela3[[#This Row],[MntTotal]]>=50), AND(AND(Tabela3[[#This Row],[Recency]]>30,Tabela3[[#This Row],[Recency]]<=45), OR(Tabela3[[#This Row],[MntTotal]]>=1500,Tabela3[[#This Row],[Ticket médio]]>=50)) ),"SIM","NÃO") -> NÃO
